Workbook

Sheet Summary
A1: Movies | B1: Group Average Rating | C1: Picked By | E1: Group Ranking | I1: Group Stats
A2: Son of a Gun | B2: =average('Data Configuration'!E2:N2) -> 2.6428571 | C2: Liam | E2: 1 | F2: {=sort(A2:A1000,B2:B1000,)} -> The Shawshank Redemption | G2: =vlookup(F2, A:B, 2,) -> 4.875 | I2: Total Movies Watched | J2: =counta(A2:A1000) -> 31
A3: Drive | B3: =average('Data Configuration'!E3:N3) -> 3.9285714 | C3: Alexis | E3: 2 | F3: 10 Things I Hate About You | G3: =vlookup(F3, A:B, 2,) -> 4.6111111 | I3: Total Hours Watched (per person) | J3: =sum('Data Configuration'!B:B)/60 -> 61.5
A4: When Harry Met Sally | B4: =average('Data Configuration'!E4:N4) -> 4.4285714 | C4: Brooke | E4: 3 | F4: Malcolm X (1992) | G4: =vlookup(F4, A:B, 2,) -> 4.5625 | I4: Total Hours Watched (group) | J4: =J3*9 -> 553.5
A5: An Evening with Beverly Luff Linn | B5: =average('Data Configuration'!E5:N5) -> 2.8333333 | C5: Alex | E5: 4 | F5: Little Women | G5: =vlookup(F5, A:B, 2,) -> 4.5333333 | I5: Total Average Rating | J5: =average(B:B) -> 3.8792475
A6: Lincoln | B6: =average('Data Configuration'!E6:N6) -> 3.6666667 | C6: Bree | E6: 5 | F6: The Town | G6: =vlookup(F6, A:B, 2,) -> 4.4714286 | I6: Highest Rated Picker | J6: =vlookup(max(B:B),B:C,2,) -> Cam
A7: Kicking and Screaming (1995) | B7: =average('Data Configuration'!E7:N7) -> 3.7222222 | C7: Dalton | E7: 6 | F7: Moonlight | G7: =vlookup(F7, A:B, 2,) -> 4.4375 | I7: Lowest Rated Picker | J7: =vlookup(MIN(B:B),B:C,2,) -> Extra Credit
A8: John Q | B8: =average('Data Configuration'!E8:N8) -> 3.8333333 | C8: Cam | E8: 7 | F8: When Harry Met Sally | G8: =vlookup(F8, A:B, 2,) -> 4.4285714 | I8: Total Oscars Nominations | J8: =sum('Data Configuration'!C:C) -> 88
A9: Heat | B9: =average('Data Configuration'!E9:N9) -> 4.2777778 | C9: Rhett | E9: 8 | F9: The Imitation Game | G9: =vlookup(F9, A:B, 2,) -> 4.3888889 | I9: Total Oscars Wins | J9: =sum('Data Configuration'!D:D) -> 15
A10: Amelie | B10: =average('Data Configuration'!E10:N10) -> 4.1333333 | C10: Hailey | E10: 9 | F10: Mystic River | G10: =vlookup(F10, A:B, 2,) -> 4.35 | I10: Most Nominations at the Oscars | J10: ='Data Configuration'!A6 -> Lincoln | K10: =max('Data Configuration'!C:C) -> 12
A11: Conclave | B11: =average('Data Configuration'!E11:N11) -> 3.5714286 | C11: Extra Credit | E11: 10 | F11: Atonement | G11: =vlookup(F11, A:B, 2,) -> 4.2857143 | I11: Most Wins at the Oscars | J11: ='Data Configuration'!A18 -> Silence of the Lambs | K11: =max('Data Configuration'!D:D) -> 5
A12: Little Women | B12: =average('Data Configuration'!E12:N12) -> 4.5333333 | C12: Extra Credit | E12: 11 | F12: Heat | G12: =vlookup(F12, A:B, 2,) -> 4.2777778
A13: Someone Great | B13: =average('Data Configuration'!E13:N13) -> 3.4777778 | C13: Brooke | E13: 12 | F13: Frances Ha | G13: =vlookup(F13, A:B, 2,) -> 4.25
A14: 10 Things I Hate About You | B14: =average('Data Configuration'!E14:N14) -> 4.6111111 | C14: Rhett | E14: 13 | F14: Silence of the Lambs | G14: =vlookup(F14, A:B, 2,) -> 4.1666667
A15: Pretty in Pink | B15: =average('Data Configuration'!E15:N15) -> 3.6111111 | C15: Hailey | E15: 14 | F15: Amelie | G15: =vlookup(F15, A:B, 2,) -> 4.1333333
A16: Atonement | B16: =average('Data Configuration'!E16:N16) -> 4.2857143 | C16: Alexis | E16: 15 | F16: My Life (1993) | G16: =vlookup(F16, A:B, 2,) -> 3.9375
A17: Life (1999) | B17: =average('Data Configuration'!E17:N17) -> 3.5555556 | C17: Cam | E17: 16 | F17: Drive | G17: =vlookup(F17, A:B, 2,) -> 3.9285714
A18: Silence of the Lambs | B18: =average('Data Configuration'!E18:N18) -> 4.1666667 | C18: Bree | E18: 17 | F18: John Q | G18: =vlookup(F18, A:B, 2,) -> 3.8333333
A19: Moonlight | B19: =average('Data Configuration'!E19:N19) -> 4.4375 | C19: Extra Credit | E19: 18 | F19: Kicking and Screaming (1995) | G19: =vlookup(F19, A:B, 2,) -> 3.7222222
A20: The Imitation Game | B20: =average('Data Configuration'!E20:N20) -> 4.3888889 | C20: Extra Credit | E20: 19 | F20: Lincoln | G20: =vlookup(F20, A:B, 2,) -> 3.6666667
A21: Dicks: The Musical | B21: =average('Data Configuration'!E21:N21) -> 0.875 | C21: Extra Credit | E21: 20 | F21: Pretty in Pink | G21: =vlookup(F21, A:B, 2,) -> 3.6111111
A22: Malcolm X (1992) | B22: =average('Data Configuration'!E22:N22) -> 4.5625 | C22: Dalton | E22: 21 | F22: Conclave | G22: =vlookup(F22, A:B, 2,) -> 3.5714286
A23: SuckerPunch (2011) | B23: =average('Data Configuration'!E23:N23) -> 3.3125 | C23: Alex | E23: 22 | F23: Life (1999) | G23: =vlookup(F23, A:B, 2,) -> 3.5555556
... A28: The Town | B28: =average('Data Configuration'!E28:N28) -> 4.4714286 | C28: Extra Credit | E28: 27 | F28: Dicks: The Musical | G28: =vlookup(F28, A:B, 2,) -> 0.875
A29: Boogie Nights | C29: Rhett | E29: 28 | F29: Boogie Nights | G29: =vlookup(F29, A:B, 2,)
A30: Lars and the Real Girl | C30: Hailey | E30: 29 | F30: Lars and the Real Girl | G30: =vlookup(F30, A:B, 2,)
A31: Horns | C31: Alex | E31: 30 | F31: Horns | G31: =vlookup(F31, A:B, 2,)
A32: Psycho | C32: Extra Credit | E32: 31 | F32: Psycho | G32: =vlookup(F32, A:B, 2,)
C33: Brooke
C34: Alexis
C35: Bree
C36: Extra Credit

Sheet Liam
A1: Movies | B1: Rating | K1: Top 10 All Time
A2: =Summary!A2 -> Son of a Gun | B2: 4.5 | D2: My Average Rating | E2: =average(B:B) -> 4.75 | K2: =Summary!L2
A3: =Summary!A3 -> Drive | B3: 5 | K3: 1
A4: =Summary!A4 -> When Harry Met Sally | B4: 4.5 | K4: 2
A5: =Summary!A5 -> An Evening with Beverly Luff Linn | B5: 5 | K5: 3
A6: =Summary!A6 -> Lincoln | B6: 5 | K6: 4
A7: =Summary!A7 -> Kicking and Screaming (1995) | B7: 4.5 | K7: 5
A8: =Summary!A8 -> John Q | B8: 5 | K8: 6
A9: =Summary!A9 -> Heat | B9: 5 | K9: 8
A10: =Summary!A10 -> Amelie | B10: 4 | K10: 8
A11: =Summary!A11 -> Conclave | B11: - | K11: 9
A12: =Summary!A12 -> Little Women | B12: 5 | K12: 10
A13: =Summary!A13 -> Someone Great | B13: 4 | K13: =Summary!L13
A14: =Summary!A14 -> 10 Things I Hate About You | B14: 5 | K14: Honorable Mentions:
A15: =Summary!A15 -> Pretty in Pink | B15: 4.5
A16: =Summary!A16 -> Atonement | B16: 4.5
A17: =Summary!A17 -> Life (1999) | B17: 4
A18: =Summary!A18 -> Silence of the Lambs | B18: 5
A19: =Summary!A19 -> Moonlight | B19: 5
A20: =Summary!A20 -> The Imitation Game | B20: 5
A21: =Summary!A21 -> Dicks: The Musical | B21: 4
A22: =Summary!A22 -> Malcolm X (1992) | B22: 5
A23: =Summary!A23 -> SuckerPunch (2011) | B23: 5
A24: =Summary!A24 -> My Life (1993) | B24: 5
A25: =Summary!A25 -> Frances Ha | B25: 4.5
A26: =Summary!A26 -> Mystic River | B26: 5
... A30: =Summary!A30 -> Lars and the Real Girl | B30: 5
A31: =Summary!A31 -> Horns
A32: =Summary!A32 -> Psycho
A33: =Summary!A33
A34: =Summary!A34
A35: =Summary!A35
A36: =Summary!A36
A37: =Summary!A37
A38: =Summary!A38
A39: =Summary!A39
A40: =Summary!A40
A41: =Summary!A41
A42: =Summary!A42
... A129: =Summary!A129

Sheet Alexis
A1: Movies | B1: Rating | K1: Top 10 All Time
A2: =Summary!A2 -> Son of a Gun | B2: 2.5 | D2: My Average Rating | E2: =average(B:B) -> 3.9210526 | K2: =Summary!L2
A3: =Summary!A3 -> Drive | B3: 4 | K3: 1
A4: =Summary!A4 -> When Harry Met Sally | B4: 4.5 | K4: 2
A5: =Summary!A5 -> An Evening with Beverly Luff Linn | B5: 2.5 | K5: 3
A6: =Summary!A6 -> Lincoln | B6: 3.5 | K6: 4
A7: =Summary!A7 -> Kicking and Screaming (1995) | B7: 3.5 | K7: 5
A8: =Summary!A8 -> John Q | B8: 3.5 | K8: 6
A9: =Summary!A9 -> Heat | B9: 4.5 | K9: 8
A10: =Summary!A10 -> Amelie | B10: 4 | K10: 8
A11: =Summary!A11 -> Conclave | B11: 4.5 | K11: 9
A12: =Summary!A12 -> Little Women | B12: 5 | K12: 10
A13: =Summary!A13 -> Someone Great | B13: 4 | K13: =Summary!L13
A14: =Summary!A14 -> 10 Things I Hate About You | B14: 5 | K14: Honorable Mentions:
A15: =Summary!A15 -> Pretty in Pink | B15: 3
A16: =Summary!A16 -> Atonement | B16: 4.5
A17: =Summary!A17 -> Life (1999) | B17: 3
A18: =Summary!A18 -> Silence of the Lambs | B18: 3.5
A19: =Summary!A19 -> Moonlight | B19: 4.5
A20: =Summary!A20 -> The Imitation Game | B20: 5
A21: =Summary!A21 -> Dicks: The Musical
A22: =Summary!A22 -> Malcolm X (1992)
A23: =Summary!A23 -> SuckerPunch (2011)
A24: =Summary!A24 -> My Life (1993)
A25: =Summary!A25 -> Frances Ha
A26: =Summary!A26 -> Mystic River
A27: =Summary!A27 -> The Shawshank Redemption
A28: =Summary!A28 -> The Town
A29: =Summary!A29 -> Boogie Nights
A30: =Summary!A30 -> Lars and the Real Girl
A31: =Summary!A31 -> Horns
A32: =Summary!A32 -> Psycho
... A129: =Summary!A129

Sheet Brooke
A1: Movies | B1: Rating | K1: Top 10 All Time
A2: =Summary!A2 -> Son of a Gun | B2: 2 | D2: My Average Rating | E2: =average(B:B) -> 3.6481481 | K2: =Summary!L2
A3: =Summary!A3 -> Drive | B3: 3.5 | K3: 1
A4: =Summary!A4 -> When Harry Met Sally | B4: 5 | K4: 2
A5: =Summary!A5 -> An Evening with Beverly Luff Linn | B5: 3 | K5: 3
A6: =Summary!A6 -> Lincoln | B6: 3 | K6: 4
A7: =Summary!A7 -> Kicking and Screaming (1995) | B7: 3.5 | K7: 5
A8: =Summary!A8 -> John Q | B8: 3 | K8: 6
A9: =Summary!A9 -> Heat | B9: 4 | K9: 8
A10: =Summary!A10 -> Amelie | B10: 4 | K10: 8
A11: =Summary!A11 -> Conclave | B11: 3.5 | K11: 9
A12: =Summary!A12 -> Little Women | B12: 5 | K12: 10
A13: =Summary!A13 -> Someone Great | B13: 4 | K13: =Summary!L13
A14: =Summary!A14 -> 10 Things I Hate About You | B14: 5 | K14: Honorable Mentions:
A15: =Summary!A15 -> Pretty in Pink | B15: 3
A16: =Summary!A16 -> Atonement | B16: 4.5
A17: =Summary!A17 -> Life (1999) | B17: 3
A18: =Summary!A18 -> Silence of the Lambs | B18: 3.5
A19: =Summary!A19 -> Moonlight | B19: 4
A20: =Summary!A20 -> The Imitation Game | B20: 4
A21: =Summary!A21 -> Dicks: The Musical | B21: 2
A22: =Summary!A22 -> Malcolm X (1992) | B22: 4.5
A23: =Summary!A23 -> SuckerPunch (2011) | B23: 2
A24: =Summary!A24 -> My Life (1993) | B24: 3.5
A25: =Summary!A25 -> Frances Ha | B25: 4.5
A26: =Summary!A26 -> Mystic River | B26: 3.5
... A28: =Summary!A28 -> The Town | B28: 3.5
A29: =Summary!A29 -> Boogie Nights
A30: =Summary!A30 -> Lars and the Real Girl
A31: =Summary!A31 -> Horns
A32: =Summary!A32 -> Psycho
A33: =Summary!A33
A34: =Summary!A34
A35: =Summary!A35
A36: =Summary!A36
A37: =Summary!A37
A38: =Summary!A38
A39: =Summary!A39
A40: =Summary!A40
... A129: =Summary!A129

Sheet Alex
A1: Movies | B1: Rating | K1: Top 10 All Time
A2: =Summary!A2 -> Son of a Gun | B2: 2.5 | D2: My Average Rating | E2: =average(B:B) -> 4 | K2: =Summary!L2
A3: =Summary!A3 -> Drive | B3: 3.5 | K3: 1. The Social Network (2010)
A4: =Summary!A4 -> When Harry Met Sally | B4: 5 | K4: 2. The Prestige (2006)
A5: =Summary!A5 -> An Evening with Beverly Luff Linn | B5: 3 | K5: 3. Dodgeball (2004)
A6: =Summary!A6 -> Lincoln | B6: 3.5 | K6: 4. Whiplash (2014)
A7: =Summary!A7 -> Kicking and Screaming (1995) | B7: 3.5 | K7: 5. The Departed (2006)
A8: =Summary!A8 -> John Q | B8: 3 | K8: 6. The Sandlot (1993)
A9: =Summary!A9 -> Heat | B9: 4.5 | K9: 7. Scott Pilgrim vs the World (2010)
A10: =Summary!A10 -> Amelie | B10: 5 | K10: 8. Comet (2014)
A11: =Summary!A11 -> Conclave | B11: 4 | K11: 9. Spider-Man 2 (2004)
A12: =Summary!A12 -> Little Women | B12: 4 | K12: 10. Princess Mononoke (1997)
A13: =Summary!A13 -> Someone Great | B13: 3.5 | K13: =Summary!L13
A14: =Summary!A14 -> 10 Things I Hate About You | B14: 4.5 | K14: Honorable Mentions:
A15: =Summary!A15 -> Pretty in Pink | B15: 3 | K15: Catch Me If You Can (2002)
A16: =Summary!A16 -> Atonement | B16: 4 | K16: Moneyball (2011)
A17: =Summary!A17 -> Life (1999) | B17: 3 | K17: Adventureland (2009)
A18: =Summary!A18 -> Silence of the Lambs | B18: 4 | K18: Atlantis: the Lost Empire (2001)
A19: =Summary!A19 -> Moonlight | K19: the Martian (2015)
A20: =Summary!A20 -> The Imitation Game | B20: 5
A21: =Summary!A21 -> Dicks: The Musical
A22: =Summary!A22 -> Malcolm X (1992) | B22: 4.5
A23: =Summary!A23 -> SuckerPunch (2011) | B23: 4
A24: =Summary!A24 -> My Life (1993) | B24: 4 | K24: Movies I might pick:
A25: =Summary!A25 -> Frances Ha | B25: 4 | K25: Horns
A26: =Summary!A26 -> Mystic River | B26: 5 | K26: Sucker Punch
A27: =Summary!A27 -> The Shawshank Redemption | B27: 5 | K27: Poolhall Junkies
A28: =Summary!A28 -> The Town | B28: 5 | K28: Deep Blue Sea
K29: The Italian Job
K30: Tank Girl
K31: Amadeus
A48: =Summary!A48
A49: =Summary!A49
A50: =Summary!A50
A51: =Summary!A51
A52: =Summary!A52
A53: =Summary!A53
A54: =Summary!A54
A55: =Summary!A55
A56: =Summary!A56
...

Sheet Bree
A1: Movies | B1: Rating | K1: Top 10 All Time
A2: =Summary!A2 -> Son of a Gun | B2: 2 | D2: My Average Rating | E2: =average(B:B) -> 3.2555556 | K2: =Summary!L2
A3: =Summary!A3 -> Drive | B3: 3 | K3: 1
A4: =Summary!A4 -> When Harry Met Sally | B4: 3 | K4: 2
A5: =Summary!A5 -> An Evening with Beverly Luff Linn | B5: 2.5 | K5: 3
A6: =Summary!A6 -> Lincoln | B6: 3.5 | K6: 4
A7: =Summary!A7 -> Kicking and Screaming (1995) | B7: 3 | K7: 5
A8: =Summary!A8 -> John Q | B8: 4 | K8: 6
A9: =Summary!A9 -> Heat | B9: 3 | K9: 8
A10: =Summary!A10 -> Amelie | B10: 4.2 | K10: 8
A11: =Summary!A11 -> Conclave | K11: 9
A12: =Summary!A12 -> Little Women | B12: 4.8 | K12: 10
A13: =Summary!A13 -> Someone Great | B13: 2.8 | K13: =Summary!L13
A14: =Summary!A14 -> 10 Things I Hate About You | B14: 3.5 | K14: Honorable Mentions:
A15: =Summary!A15 -> Pretty in Pink | B15: 3.5
A16: =Summary!A16 -> Atonement | B16: 4
A17: =Summary!A17 -> Life (1999) | B17: 3.5
A18: =Summary!A18 -> Silence of the Lambs | B18: 4
A19: =Summary!A19 -> Moonlight | B19: 3
A20: =Summary!A20 -> The Imitation Game | B20: 4.5
A21: =Summary!A21 -> Dicks: The Musical | B21: -5
A22: =Summary!A22 -> Malcolm X (1992) | B22: 4
A23: =Summary!A23 -> SuckerPunch (2011) | B23: 3
A24: =Summary!A24 -> My Life (1993) | B24: 4
A25: =Summary!A25 -> Frances Ha | B25: 3
A26: =Summary!A26 -> Mystic River | B26: 4.8
... A28: =Summary!A28 -> The Town | B28: 3.8
A29: =Summary!A29 -> Boogie Nights
A30: =Summary!A30 -> Lars and the Real Girl | B30: 3.5
A31: =Summary!A31 -> Horns
A32: =Summary!A32 -> Psycho
A33: =Summary!A33
A34: =Summary!A34
A35: =Summary!A35
A36: =Summary!A36
A37: =Summary!A37
A38: =Summary!A38
A39: =Summary!A39
A40: =Summary!A40
A41: =Summary!A41
...

Sheet Dalton
A1: Movies | B1: Rating | K1: Top 10 All Time
A2: =Summary!A2 -> Son of a Gun | B2: 2.5 | D2: My Average Rating | E2: =average(B:B) -> 4 | K2: =Summary!L2
A3: =Summary!A3 -> Drive | B3: 4 | K3: 1
A4: =Summary!A4 -> When Harry Met Sally | B4: 4 | K4: 2
A5: =Summary!A5 -> An Evening with Beverly Luff Linn | B5: 2.5 | K5: 3
A6: =Summary!A6 -> Lincoln | B6: 4 | K6: 4
A7: =Summary!A7 -> Kicking and Screaming (1995) | B7: 4 | K7: 5
A8: =Summary!A8 -> John Q | B8: 3.5 | K8: 6
A9: =Summary!A9 -> Heat | B9: 4.5 | K9: 8
A10: =Summary!A10 -> Amelie | B10: 4.5 | K10: 8
A11: =Summary!A11 -> Conclave | B11: 5 | K11: 9
A12: =Summary!A12 -> Little Women | B12: 5 | K12: 10
A13: =Summary!A13 -> Someone Great | B13: 3 | K13: =Summary!L13
A14: =Summary!A14 -> 10 Things I Hate About You | B14: 5 | K14: Honorable Mentions:
A15: =Summary!A15 -> Pretty in Pink | B15: 3
A16: =Summary!A16 -> Atonement | B16: 4
A17: =Summary!A17 -> Life (1999) | B17: 3
A18: =Summary!A18 -> Silence of the Lambs | B18: 3.5
A19: =Summary!A19 -> Moonlight | B19: 5
A20: =Summary!A20 -> The Imitation Game | B20: 5
A21: =Summary!A21 -> Dicks: The Musical | B21: N/a
A22: =Summary!A22 -> Malcolm X (1992) | B22: 5
A23: =Summary!A23 -> SuckerPunch (2011) | B23: 3
A24: =Summary!A24 -> My Life (1993) | B24: 3.5
A25: =Summary!A25 -> Frances Ha | B25: 5
A26: =Summary!A26 -> Mystic River | B26: 4
A27: =Summary!A27 -> The Shawshank Redemption | B27: 4.5
A28: =Summary!A28 -> The Town | B28: N/a
A29: =Summary!A29 -> Boogie Nights
A30: =Summary!A30 -> Lars and the Real Girl
A31: =Summary!A31 -> Horns
A32: =Summary!A32 -> Psycho
A33: =Summary!A33
A34: =Summary!A34
A35: =Summary!A35
A36: =Summary!A36
A37: =Summary!A37
A38: =Summary!A38
A39: =Summary!A39
A40: =Summary!A40
...

Sheet Cam
A1: Movies | B1: Rating | K1: Top 10 All Time
A2: =Summary!A2 -> Son of a Gun | D2: My Average Rating | E2: =average(B:B) -> 3.9166667 | K2: =Summary!L2
A3: =Summary!A3 -> Drive | K3: 1
A4: =Summary!A4 -> When Harry Met Sally | K4: 2
A5: =Summary!A5 -> An Evening with Beverly Luff Linn | B5: 2 | K5: 3
A6: =Summary!A6 -> Lincoln | B6: 3 | K6: 4
A7: =Summary!A7 -> Kicking and Screaming (1995) | B7: 4 | K7: 5
A8: =Summary!A8 -> John Q | B8: 5 | K8: 6
A9: =Summary!A9 -> Heat | B9: 4 | K9: 8
A10: =Summary!A10 -> Amelie | B10: 3 | K10: 8
A11: =Summary!A11 -> Conclave | B11: 3 | K11: 9
A12: =Summary!A12 -> Little Women | B12: 3 | K12: 10
A13: =Summary!A13 -> Someone Great | B13: 3.5 | K13: =Summary!L13
A14: =Summary!A14 -> 10 Things I Hate About You | B14: 4 | K14: Honorable Mentions:
A15: =Summary!A15 -> Pretty in Pink | B15: 4
A16: =Summary!A16 -> Atonement
A17: =Summary!A17 -> Life (1999) | B17: 5
A18: =Summary!A18 -> Silence of the Lambs | B18: 4
A19: =Summary!A19 -> Moonlight | B19: 5
A20: =Summary!A20 -> The Imitation Game | B20: 4
A21: =Summary!A21 -> Dicks: The Musical
A22: =Summary!A22 -> Malcolm X (1992) | B22: 5
A23: =Summary!A23 -> SuckerPunch (2011) | B23: 3
A24: =Summary!A24 -> My Life (1993) | B24: 4
A25: =Summary!A25 -> Frances Ha | B25: 4
A26: =Summary!A26 -> Mystic River | B26: 4.5
A27: =Summary!A27 -> The Shawshank Redemption | B27: 5
A28: =Summary!A28 -> The Town | B28: 5
A29: =Summary!A29 -> Boogie Nights | B29: 3.5
A30: =Summary!A30 -> Lars and the Real Girl | B30: 3.5
A31: =Summary!A31 -> Horns
A32: =Summary!A32 -> Psycho
A33: =Summary!A33
A34: =Summary!A34
A35: =Summary!A35
A36: =Summary!A36
A37: =Summary!A37
A38: =Summary!A38
A39: =Summary!A39
A40: =Summary!A40
...

Sheet Rhett
A1: Movies | B1: Rating | K1: Top 10 All Time
A2: =Summary!A2 -> Son of a Gun | B2: 2.5 | D2: My Average Rating | E2: =average(B:B) -> 4.0555556 | K2: =Summary!L2
A3: =Summary!A3 -> Drive | B3: 4.5 | K3: 1
A4: =Summary!A4 -> When Harry Met Sally | B4: 5 | K4: 2
A5: =Summary!A5 -> An Evening with Beverly Luff Linn | B5: 3 | K5: 3
A6: =Summary!A6 -> Lincoln | B6: 4 | K6: 4
A7: =Summary!A7 -> Kicking and Screaming (1995) | B7: 3.5 | K7: 5
A8: =Summary!A8 -> John Q | B8: 3.5 | K8: 6
A9: =Summary!A9 -> Heat | B9: 5 | K9: 8
A10: =Summary!A10 -> Amelie | B10: 4.5 | K10: 8
A11: =Summary!A11 -> Conclave | B11: 4 | K11: 9
A12: =Summary!A12 -> Little Women | B12: 5 | K12: 10
A13: =Summary!A13 -> Someone Great | B13: 3 | K13: =Summary!L13
A14: =Summary!A14 -> 10 Things I Hate About You | B14: 4.5 | K14: Honorable Mentions:
A15: =Summary!A15 -> Pretty in Pink | B15: 3.5
A16: =Summary!A16 -> Atonement | B16: 4.5
A17: =Summary!A17 -> Life (1999) | B17: 3.5
A18: =Summary!A18 -> Silence of the Lambs | B18: 5
A19: =Summary!A19 -> Moonlight | B19: 5
A20: =Summary!A20 -> The Imitation Game | B20: 4
A21: =Summary!A21 -> Dicks: The Musical | B21: 2.5
A22: =Summary!A22 -> Malcolm X (1992) | B22: 4.5
A23: =Summary!A23 -> SuckerPunch (2011) | B23: 3
A24: =Summary!A24 -> My Life (1993) | B24: 3.5
A25: =Summary!A25 -> Frances Ha | B25: 5
A26: =Summary!A26 -> Mystic River | B26: 4
... A28: =Summary!A28 -> The Town | B28: 4.5
A29: =Summary!A29 -> Boogie Nights
A30: =Summary!A30 -> Lars and the Real Girl
A31: =Summary!A31 -> Horns
A32: =Summary!A32 -> Psycho
A33: =Summary!A33
A34: =Summary!A34
A35: =Summary!A35
A36: =Summary!A36
A37: =Summary!A37
A38: =Summary!A38
A39: =Summary!A39
A40: =Summary!A40
... A129: =Summary!A129

Sheet Hailey
A1: Movies | B1: Rating | L1: Top 10 All Time
A2: =Summary!A2 -> Son of a Gun | D2: My Average Rating | E2: =average(B:B) -> 3.875 | L2: =Summary!M2
A3: =Summary!A3 -> Drive | L3: 1
A4: =Summary!A4 -> When Harry Met Sally | L4: 2
A5: =Summary!A5 -> An Evening with Beverly Luff Linn | B5: 2 | L5: 3
A6: =Summary!A6 -> Lincoln | B6: 3.5 | L6: 4
A7: =Summary!A7 -> Kicking and Screaming (1995) | B7: 4 | L7: 5
A8: =Summary!A8 -> John Q | B8: 4 | L8: 6
A9: =Summary!A9 -> Heat | B9: 4 | L9: 8
A10: =Summary!A10 -> Amelie | B10: 4 | L10: 8
A11: =Summary!A11 -> Conclave | B11: 1 | L11: 9
A12: =Summary!A12 -> Little Women | B12: 4 | L12: 10
A13: =Summary!A13 -> Someone Great | B13: 3.5 | L13: =Summary!M13
A14: =Summary!A14 -> 10 Things I Hate About You | B14: 5 | L14: Honorable Mentions:
A15: =Summary!A15 -> Pretty in Pink | B15: 5
A16: =Summary!A16 -> Atonement
A17: =Summary!A17 -> Life (1999) | B17: 4
A18: =Summary!A18 -> Silence of the Lambs | B18: 5
A19: =Summary!A19 -> Moonlight | B19: 4
A20: =Summary!A20 -> The Imitation Game | B20: 3
A21: =Summary!A21 -> Dicks: The Musical
A22: =Summary!A22 -> Malcolm X (1992) | B22: 4
A23: =Summary!A23 -> SuckerPunch (2011) | B23: 3.5
A24: =Summary!A24 -> My Life (1993) | B24: 4
A25: =Summary!A25 -> Frances Ha | B25: 4
A26: =Summary!A26 -> Mystic River | B26: 4
A27: =Summary!A27 -> The Shawshank Redemption | B27: 5
A28: =Summary!A28 -> The Town | B28: 4.5
A29: =Summary!A29 -> Boogie Nights | B29: 3.5
A30: =Summary!A30 -> Lars and the Real Girl | B30: 4.5
A31: =Summary!A31 -> Horns
A32: =Summary!A32 -> Psycho
A33: =Summary!A33
A34: =Summary!A34
A35: =Summary!A35
A36: =Summary!A36
A37: =Summary!A37
A38: =Summary!A38
A39: =Summary!A39
A40: =Summary!A40
...

Sheet Nick
A1: Movies | B1: Rating | K1: Top 10 All Time
A2: =Summary!A2 -> Son of a Gun | D2: My Average Rating | E2: =average(B:B) -> #DIV/0! | K2: =Summary!L2
A3: =Summary!A3 -> Drive | K3: 1
A4: =Summary!A4 -> When Harry Met Sally | K4: 2
A5: =Summary!A5 -> An Evening with Beverly Luff Linn | K5: 3
A6: =Summary!A6 -> Lincoln | K6: 4
A7: =Summary!A7 -> Kicking and Screaming (1995) | K7: 5
A8: =Summary!A8 -> John Q | K8: 6
A9: =Summary!A9 -> Heat | K9: 8
A10: =Summary!A10 -> Amelie | K10: 8
A11: =Summary!A11 -> Conclave | K11: 9
A12: =Summary!A12 -> Little Women | K12: 10
A13: =Summary!A13 -> Someone Great | K13: =Summary!L13
A14: =Summary!A14 -> 10 Things I Hate About You | K14: Honorable Mentions:
A15: =Summary!A15 -> Pretty in Pink
A16: =Summary!A16 -> Atonement
A17: =Summary!A17 -> Life (1999)
A18: =Summary!A18 -> Silence of the Lambs
A19: =Summary!A19 -> Moonlight
A20: =Summary!A20 -> The Imitation Game
A21: =Summary!A21 -> Dicks: The Musical
A22: =Summary!A22 -> Malcolm X (1992)
A23: =Summary!A23 -> SuckerPunch (2011)
A24: =Summary!A24 -> My Life (1993)
A25: =Summary!A25 -> Frances Ha
A26: =Summary!A26 -> Mystic River
... A129: =Summary!A129

Sheet Data Configuration
B1: Minutes | C1: Academy Awards Nominations | D1: Academy Awards Wins | E1: Liam | F1: Alexis | G1: Brooke | H1: Alex | I1: Bree | J1: Dalton | K1: Cam | L1: Rhett | M1: Hailey | N1: Nick
A2: =Summary!A2 -> Son of a Gun | B2: 108 | C2: 0 | D2: 0 | E2: =Liam!B2 -> 4.5 | F2: =Alexis!B2 -> 2.5 | G2: =Brooke!B2 -> 2 | H2: =Alex!B2 -> 2.5 | I2: =Bree!B2 -> 2 | J2: =Dalton!B2 -> 2.5 | K2: =Cam!B2 | L2: =Rhett!B2 -> 2.5 | M2: =Hailey!B2 | N2: =Nick!B2
A3: =Summary!A3 -> Drive | B3: 100 | C3: 1 | D3: 0 | E3: =Liam!B3 -> 5 | F3: =Alexis!B3 -> 4 | G3: =Brooke!B3 -> 3.5 | H3: =Alex!B3 -> 3.5 | I3: =Bree!B3 -> 3 | J3: =Dalton!B3 -> 4 | K3: =Cam!B3 | L3: =Rhett!B3 -> 4.5 | M3: =Hailey!B3 | N3: =Nick!B3
A4: =Summary!A4 -> When Harry Met Sally | B4: 96 | C4: 1 | D4: 0 | E4: =Liam!B4 -> 4.5 | F4: =Alexis!B4 -> 4.5 | G4: =Brooke!B4 -> 5 | H4: =Alex!B4 -> 5 | I4: =Bree!B4 -> 3 | J4: =Dalton!B4 -> 4 | K4: =Cam!B4 | L4: =Rhett!B4 -> 5 | M4: =Hailey!B4 | N4: =Nick!B4
A5: =Summary!A5 -> An Evening with Beverly Luff Linn | B5: 108 | C5: 0 | D5: 0 | E5: =Liam!B5 -> 5 | F5: =Alexis!B5 -> 2.5 | G5: =Brooke!B5 -> 3 | H5: =Alex!B5 -> 3 | I5: =Bree!B5 -> 2.5 | J5: =Dalton!B5 -> 2.5 | K5: =Cam!B5 -> 2 | L5: =Rhett!B5 -> 3 | M5: =Hailey!B5 -> 2 | N5: =Nick!B5
A6: =Summary!A6 -> Lincoln | B6: 149 | C6: 12 | D6: 2 | E6: =Liam!B6 -> 5 | F6: =Alexis!B6 -> 3.5 | G6: =Brooke!B6 -> 3 | H6: =Alex!B6 -> 3.5 | I6: =Bree!B6 -> 3.5 | J6: =Dalton!B6 -> 4 | K6: =Cam!B6 -> 3 | L6: =Rhett!B6 -> 4 | M6: =Hailey!B6 -> 3.5 | N6: =Nick!B6
A7: =Summary!A7 -> Kicking and Screaming (1995) | B7: 96 | C7: 0 | D7: 0 | E7: =Liam!B7 -> 4.5 | F7: =Alexis!B7 -> 3.5 | G7: =Brooke!B7 -> 3.5 | H7: =Alex!B7 -> 3.5 | I7: =Bree!B7 -> 3 | J7: =Dalton!B7 -> 4 | K7: =Cam!B7 -> 4 | L7: =Rhett!B7 -> 3.5 | M7: =Hailey!B7 -> 4 | N7: =Nick!B7
A8: =Summary!A8 -> John Q | B8: 116 | C8: 0 | D8: 0 | E8: =Liam!B8 -> 5 | F8: =Alexis!B8 -> 3.5 | G8: =Brooke!B8 -> 3 | H8: =Alex!B8 -> 3 | I8: =Bree!B8 -> 4 | J8: =Dalton!B8 -> 3.5 | K8: =Cam!B8 -> 5 | L8: =Rhett!B8 -> 3.5 | M8: =Hailey!B8 -> 4 | N8: =Nick!B8
A9: =Summary!A9 -> Heat | B9: 170 | C9: 0 | D9: 0 | E9: =Liam!B9 -> 5 | F9: =Alexis!B9 -> 4.5 | G9: =Brooke!B9 -> 4 | H9: =Alex!B9 -> 4.5 | I9: =Bree!B9 -> 3 | J9: =Dalton!B9 -> 4.5 | K9: =Cam!B9 -> 4 | L9: =Rhett!B9 -> 5 | M9: =Hailey!B9 -> 4 | N9: =Nick!B9
A10: =Summary!A10 -> Amelie | B10: 122 | C10: 5 | D10: 0 | E10: =Liam!B10 -> 4 | F10: =Alexis!B10 -> 4 | G10: =Brooke!B10 -> 4 | H10: =Alex!B10 -> 5 | I10: =Bree!B10 -> 4.2 | J10: =Dalton!B10 -> 4.5 | K10: =Cam!B10 -> 3 | L10: =Rhett!B10 -> 4.5 | M10: =Hailey!B10 -> 4 | N10: =Nick!B10
A11: =Summary!A11 -> Conclave | B11: 120 | C11: 8 | D11: 1 | E11: =Liam!B11 -> - | F11: =Alexis!B11 -> 4.5 | G11: =Brooke!B11 -> 3.5 | H11: =Alex!B11 -> 4 | I11: =Bree!B11 | J11: =Dalton!B11 -> 5 | K11: =Cam!B11 -> 3 | L11: =Rhett!B11 -> 4 | M11: =Hailey!B11 -> 1 | N11: =Nick!B11
A12: =Summary!A12 -> Little Women | B12: 135 | C12: 6 | D12: 1 | E12: =Liam!B12 -> 5 | F12: =Alexis!B12 -> 5 | G12: =Brooke!B12 -> 5 | H12: =Alex!B12 -> 4 | I12: =Bree!B12 -> 4.8 | J12: =Dalton!B12 -> 5 | K12: =Cam!B12 -> 3 | L12: =Rhett!B12 -> 5 | M12: =Hailey!B12 -> 4 | N12: =Nick!B12
A13: =Summary!A13 -> Someone Great | B13: 92 | C13: 0 | D13: 0 | E13: =Liam!B13 -> 4 | F13: =Alexis!B13 -> 4 | G13: =Brooke!B13 -> 4 | H13: =Alex!B13 -> 3.5 | I13: =Bree!B13 -> 2.8 | J13: =Dalton!B13 -> 3 | K13: =Cam!B13 -> 3.5 | L13: =Rhett!B13 -> 3 | M13: =Hailey!B13 -> 3.5 | N13: =Nick!B13
... A32: =Summary!A32 -> Psycho | B32: 109 | C32: 4 | D32: 0 | E32: =Liam!B32 | F32: =Alexis!B32 | G32: =Brooke!B32 | H32: =Alex!B32 | I32: =Bree!B32 | J32: =Dalton!B32 | K32: =Cam!B32 | L32: =Rhett!B32 | M32: =Hailey!B32 | N32: =Nick!B32
A33: =Summary!A33 | E33: =Liam!B33 | F33: =Alexis!B33 | G33: =Brooke!B33 | H33: =Alex!B33 | I33: =Bree!B33 | J33: =Dalton!B33 | K33: =Cam!B33 | L33: =Rhett!B33 | M33: =Hailey!B33 | N33: =Nick!B33
A34: =Summary!A34 | E34: =Liam!B34 | F34: =Alexis!B34 | G34: =Brooke!B34 | H34: =Alex!B34 | I34: =Bree!B34 | J34: =Dalton!B34 | K34: =Cam!B34 | L34: =Rhett!B34 | M34: =Hailey!B34 | N34: =Nick!B34
A35: =Summary!A35 | E35: =Liam!B35 | F35: =Alexis!B35 | G35: =Brooke!B35 | H35: =Alex!B35 | I35: =Bree!B35 | J35: =Dalton!B35 | K35: =Cam!B35 | L35: =Rhett!B35 | M35: =Hailey!B35 | N35: =Nick!B35
A36: =Summary!A36 | E36: =Liam!B36 | F36: =Alexis!B36 | G36: =Brooke!B36 | H36: =Alex!B36 | I36: =Bree!B36 | J36: =Dalton!B36 | K36: =Cam!B36 | L36: =Rhett!B36 | M36: =Hailey!B36 | N36: =Nick!B36
A37: =Summary!A37 | E37: =Liam!B37 | F37: =Alexis!B37 | G37: =Brooke!B37 | H37: =Alex!B37 | I37: =Bree!B37 | J37: =Dalton!B37 | K37: =Cam!B37 | L37: =Rhett!B37 | M37: =Hailey!B37 | N37: =Nick!B37
A38: =Summary!A38 | E38: =Liam!B38 | F38: =Alexis!B38 | G38: =Brooke!B38 | H38: =Alex!B38 | I38: =Bree!B38 | J38: =Dalton!B38 | K38: =Cam!B38 | L38: =Rhett!B38 | M38: =Hailey!B38 | N38: =Nick!B38
A39: =Summary!A39 | E39: =Liam!B39 | F39: =Alexis!B39 | G39: =Brooke!B39 | H39: =Alex!B39 | I39: =Bree!B39 | J39: =Dalton!B39 | K39: =Cam!B39 | L39: =Rhett!B39 | M39: =Hailey!B39 | N39: =Nick!B39
A40: =Summary!A40 | E40: =Liam!B40 | F40: =Alexis!B40 | G40: =Brooke!B40 | H40: =Alex!B40 | I40: =Bree!B40 | J40: =Dalton!B40 | K40: =Cam!B40 | L40: =Rhett!B40 | M40: =Hailey!B40 | N40: =Nick!B40
A41: =Summary!A41 | E41: =Liam!B41 | F41: =Alexis!B41 | G41: =Brooke!B41 | H41: =Alex!B41 | I41: =Bree!B41 | J41: =Dalton!B41 | K41: =Cam!B41 | L41: =Rhett!B41 | M41: =Hailey!B41 | N41: =Nick!B41
A42: =Summary!A42 | E42: =Liam!B42 | F42: =Alexis!B42 | G42: =Brooke!B42 | H42: =Alex!B42 | I42: =Bree!B42 | J42: =Dalton!B42 | K42: =Cam!B42 | L42: =Rhett!B42 | M42: =Hailey!B42 | N42: =Nick!B42
A43: =Summary!A43 | E43: =Liam!B43 | F43: =Alexis!B43 | G43: =Brooke!B43 | H43: =Alex!B43 | I43: =Bree!B43 | J43: =Dalton!B43 | K43: =Cam!B43 | L43: =Rhett!B43 | M43: =Hailey!B43 | N43: =Nick!B43
A44: =Summary!A44 | E44: =Liam!B44 | F44: =Alexis!B44 | G44: =Brooke!B44 | H44: =Alex!B44 | I44: =Bree!B44 | J44: =Dalton!B44 | K44: =Cam!B44 | L44: =Rhett!B44 | M44: =Hailey!B44 | N44: =Nick!B44
... A227: =Summary!A227 | E227: =Liam!B227 | F227: =Alexis!B227 | G227: =Brooke!B227 | H227: =Alex!B227 | I227: =Bree!B227 | J227: =Dalton!B227 | K227: =Cam!B227 | L227: =Rhett!B227 | M227: =Hailey!B227 | N227: =Nick!B227
E228: =Liam!B228 | F228: =Alexis!B228 | G228: =Brooke!B228 | H228: =Alex!B228 | I228: =Bree!B228 | J228: =Dalton!B228 | K228: =Cam!B228 | L228: =Rhett!B228 | M228: =Hailey!B228 | N228: =Nick!B228
E229: =Liam!B229 | F229: =Alexis!B229 | G229: =Brooke!B229 | H229: =Alex!B229 | I229: =Bree!B229 | J229: =Dalton!B229 | K229: =Cam!B229 | L229: =Rhett!B229 | M229: =Hailey!B229 | N229: =Nick!B229
E230: =Liam!B230 | F230: =Alexis!B230 | G230: =Brooke!B230 | H230: =Alex!B230 | I230: =Bree!B230 | J230: =Dalton!B230 | K230: =Cam!B230 | L230: =Rhett!B230 | M230: =Hailey!B230 | N230: =Nick!B230
E231: =Liam!B231 | F231: =Alexis!B231 | G231: =Brooke!B231 | H231: =Alex!B231 | I231: =Bree!B231 | J231: =Dalton!B231 | K231: =Cam!B231 | L231: =Rhett!B231 | M231: =Hailey!B231 | N231: =Nick!B231
E232: =Liam!B232 | F232: =Alexis!B232 | G232: =Brooke!B232 | H232: =Alex!B232 | I232: =Bree!B232 | J232: =Dalton!B232 | K232: =Cam!B232 | L232: =Rhett!B232 | M232: =Hailey!B232 | N232: =Nick!B232
E233: =Liam!B233 | F233: =Alexis!B233 | G233: =Brooke!B233 | H233: =Alex!B233 | I233: =Bree!B233 | J233: =Dalton!B233 | K233: =Cam!B233 | L233: =Rhett!B233 | M233: =Hailey!B233 | N233: =Nick!B233
E234: =Liam!B234 | F234: =Alexis!B234 | G234: =Brooke!B234 | H234: =Alex!B234 | I234: =Bree!B234 | J234: =Dalton!B234 | K234: =Cam!B234 | L234: =Rhett!B234 | M234: =Hailey!B234 | N234: =Nick!B234
E235: =Liam!B235 | F235: =Alexis!B235 | G235: =Brooke!B235 | H235: =Alex!B235 | I235: =Bree!B235 | J235: =Dalton!B235 | K235: =Cam!B235 | L235: =Rhett!B235 | M235: =Hailey!B235 | N235: =Nick!B235
E236: =Liam!B236 | F236: =Alexis!B236 | G236: =Brooke!B236 | H236: =Alex!B236 | I236: =Bree!B236 | J236: =Dalton!B236 | K236: =Cam!B236 | L236: =Rhett!B236 | M236: =Hailey!B236 | N236: =Nick!B236
E237: =Liam!B237 | F237: =Alexis!B237 | G237: =Brooke!B237 | H237: =Alex!B237 | I237: =Bree!B237 | J237: =Dalton!B237 | K237: =Cam!B237 | L237: =Rhett!B237 | M237: =Hailey!B237 | N237: =Nick!B237
E238: =Liam!B238 | F238: =Alexis!B238 | G238: =Brooke!B238 | H238: =Alex!B238 | I238: =Bree!B238 | J238: =Dalton!B238 | K238: =Cam!B238 | L238: =Rhett!B238 | M238: =Hailey!B238 | N238: =Nick!B238
E239: =Liam!B239 | F239: =Alexis!B239 | G239: =Brooke!B239 | H239: =Alex!B239 | I239: =Bree!B239 | J239: =Dalton!B239 | K239: =Cam!B239 | L239: =Rhett!B239 | M239: =Hailey!B239 | N239: =Nick!B239
... E246: =Liam!B246 | F246: =Alexis!B246 | G246: =Brooke!B246 | H246: =Alex!B246 | I246: =Bree!B246 | J246: =Dalton!B246 | K246: =Cam!B246 | L246: =Rhett!B246 | M246: =Hailey!B246 | N246: =Nick!B246
...
